Workbook
Name POWER_USER_LINK_1C8468DF_3981_452A_988B_B237ACC8F15D: '[1]Financing Baseline'!$C$128:$P$134
Name POWER_USER_LINK_1E1BD091_4625_4444_97D5_A6FF49E7A790: '[1]Financing Baseline'!$D$109:$P$115
Name POWER_USER_LINK_5C354A30_39B7_4BC2_A1BC_772102FD5A07: '[1]Financing Baseline'!$D$109:$P$115
Name POWER_USER_LINK_660DD32F_20D2_4943_85B4_C2277CFD14E1: '[1]Financing Baseline'!$D$109:$P$115
Name POWER_USER_LINK_82AA7F52_0AA6_445C_99A0_BCDBE6072606: '[1]Financing Baseline'!$C$128:$P$134
Name POWER_USER_LINK_8811B919_6076_4DE1_8A8A_1591D1C3F1D3: '[1]Financing Baseline'!$D$109:$P$115
Name POWER_USER_LINK_88A461FD_7EA7_42BC_9FB8_413E38E7215B: '[1]Financing Baseline'!$D$101:$P$107
Name POWER_USER_LINK_8BD0C2AE_99B7_4293_8693_DF676F2E4705: '[1]Financing Baseline'!$D$93:$P$99
Name POWER_USER_LINK_9E537006_98B2_46EC_8819_DD41353322F7: '[1]Financing Baseline'!$C$128:$P$134
Name POWER_USER_LINK_A4EC7F36_8FF3_4488_B633_885239D87E7F: '[1]Financing Baseline'!$D$93:$P$99
Name POWER_USER_LINK_C0E51312_0DE1_43B3_B0BB_32513878B4D0: '[1]Financing Baseline'!$C$128:$P$134
Name POWER_USER_LINK_C40E531F_E888_434D_B256_633316EE9B99: '[1]Financing Baseline'!$D$109:$P$115
Name POWER_USER_LINK_C670BFA9_1E80_4883_8B1D_2D7BF8BEB301: '[1]Financing Baseline'!$C$128:$P$134
Name POWER_USER_LINK_C8E7FDEE_D21E_4649_A767_4F5C55FA2FC8: '[1]Financing Baseline'!$D$101:$P$107
Name POWER_USER_LINK_C904F0C4_2D79_4048_B89A_3A3D35880395: '[1]Financing Baseline'!$D$101:$P$107
Name POWER_USER_LINK_CB729846_7F59_4903_A12A_D4277681E321: '[1]Financing Baseline'!$D$93:$J$99
Name POWER_USER_LINK_E7C2DD64_3477_4661_87F3_FF98A191BC47: '[1]Financing Baseline'!$D$101:$P$107
Name POWER_USER_LINK_ECA9A96E_360E_419C_ABD3_88BEB06ADB97: '[1]Financing Baseline'!$D$101:$P$107

Sheet Definitions
B3: MINFin
B4: Model for Informated National Financing
B7: MINFin Input File - Guide | E7: MINFin is a sectoral cashflow model ….......
B9: Document structure
B11: Parameter Constraints
B12: Financing Baseline
B13: Funding Baseline
B15: Parameter Constraints | E15: Financing Baseline | H15: Funding Baseline | K15: Technologies
B16: Name | C16: Description | E16: Name | F16: Description | H16: Name | I16: Description | K16: Name | L16: Description | M16: Classification
B17: CurrencyExchangeRate | D17: - | E17: Name of Project | G17: - | H17: Name | J17: - | K17: PWRBIO001 | L17: Biomass power plant | M17: Biomass
B18: GDPGrowth | C18: The parameter defines annual percentage growth rate of GDP. | D18: - | E18: Name of Financier | G18: - | H18: Name of Financier | J18: - | K18: PWRCOA001 | L18: Coal power plant | M18: Coal
B19: AnnualGDP | D19: - | E19: Technology | G19: - | H19: Technology | I19: The technology parameter encompasses different power-generation technologies. | J19: - | K19: PWRGEO | L19: Geothermal power plant | M19: Geothermal
B20: Elasticity of energy demand | D20: - | E20: Source | G20: - | H20: Source | J20: - | K20: PWROHC001 | L20: Light fuel oil power plant | M20: Oil
B21: CAGR of real energy price | D21: - | E21: Financing Source | G21: - | H21: Volume of Finance | I21: The parameter volume of finance refers to the sum of money involved in financial transactions from a financier to a project, expressed in millions of units of the local currency. | J21: - | K21: PWROHC002 | L21: Oil fired gas turbine - SCGT | M21: Oil
B22: DiscountRate | C22: The discount rate parameter represents the percentage rate used to discount future cash flows to their present value. | D22: - | E22: Type of Finance | G22: - | H22: GovShare | J22: - | K22: PWRNGS001 | L22: Natural gas power plant - CCGT | M22: Gas
B23: AnnualLoanRepayments | D23: - | E23: Financing Sector | G23: - | H23: Year | J23: - | K23: PWRNGS002 | L23: Nautral gas power plant - SCGT | M23: Gas
B24: BuildTime | C24: The build time parameter refers to the duration, in years, required for the construction of a power plant from the project's start to its completion and operational readiness. | D24: - | E24: Financial Institution | G24: - | H24: Currency | J24: - | K24: PWRSOL001 | L24: Solar PV - Utility scale | M24: Solar PV
B25: Weighting | C25: The weighting parameter indicates the relative contribution of four finance categories (DomesticCommercial, DomesticConcessional, InternationalCommercial, InternationalConcessional) to the total financing of each technology. The sum of these contributions from the four categories should equal 1 for each technology. | D25: - | E25: Origin of Finance | G25: - | J25: - | K25: PWRCSP001 | L25: CSP - Without storage | M25: CSP
B26: WACC | C26: The Weighted Average Cost of Capital (WACC) parameter reflects the combined cost of capital from various sources, including both debt and equity. It should be determined by weighting the cost of each capital type based on its proportion of the total capital and then summing them together. | D26: - | E26: Volume of Finance | G26: - | J26: - | K26: PWRCSP002 | L26: CSP - With storage | M26: CSP
B27: GracePeriod | C27: The grace period parameter represents the duration, measured in years, from the loan's issuance to the initial repayment of principal. | D27: - | E27: Rate | G27: - | J27: - | K27: PWRHYD001 | L27: Hydropower plant - Large dam (>100MW) | M27: Hydropower
B28: Term | C28: The parameter "term" denotes the duration, in years, of a loan or, in the case of equity, the lifespan of the project being financed. | D28: - | E28: Term | F28: The parameter "term" denotes the duration, in years, of a loan or, in the case of equity, the lifespan of the project being financed. | G28: - | J28: - | K28: PWRHYD002 | L28: Hydropower plant - Medium (10-100MW) | M28: Hydropower
B29: CAGRGovtSpending | C29: The Compound Annual Growth Rate (CAGR) of Government Spending parameter defines the annualised percentage rate of growth of government budget funding over the modelled period. XXX Should be considered. Downstream oil and gas spending should not be included. | D29: - | E29: Grace period | F29: The grace period parameter represents the duration, measured in years, from the loan's issuance to the initial repayment of principal. | G29: - | J29: - | K29: PWRHYD003 | L29: Hydropower plant - Small (<10MW) | M29: Hydropower
B30: CAGRSOECashflow | D30: - | E30: Schedule | G30: - | J30: - | K30: PWRWND001 | L30: Wind farm - Onshore | M30: Onshore Wind
B31: CAGRGrants | C31: The Compound Annual Growth Rate (CAGR) of grants parameter defines the annualised percentage rate of growth for grant funding over the modelled period. | D31: - | E31: Project Close | F31: This parameter marks financial closure, indicating the year when the procurement phase ends with the signing of the PPP contract, meeting financing prerequisites, and securing funds for Project Company to start construction. | G31: - | J31: - | K31: PWRWND002 | L31: Wind farm - Offshore | M31: Offshore Wind
D32: - | E32: Start Year | F32: The Start Year parameter specifies the year when financing repayment begins, initiating from loan year 0. | G32: - | J32: - | K32: PWRNUC | L32: Nuclear power plant | M32: Nuclear
B33: Currencies | E33: Currency | G33: - | K33: PWRTRN | L33: Electricity transmission | M33: Transmission
B34: Code | C34: Currency | G34: - | K34: PWRDIST | L34: Electricity distribution | M34: Distribution
B35: USD | C35: US Dollar | G35: - | K35: PWROHC003 | L35: Light fuel oil standalone generator (1kW) | M35: Oil
B36: CAD | C36: Canadian Dollar | E36: Scenarios | G36: - | K36: PWRSOL002 | L36: Solar PV - distributed with storage | M36: Solar PV
B37: CNY | C37: Chinese Renminbi | E37: Name | F37: Description | G37: - | K37: PWRHYD004 | L37: Hydropower plant - Off-grid | M37: Hydropower
B38: GBP | C38: British Pound | E38: NetZero | F38: Scenario Name 1 (More ambitious) | G38: - | K38: PWRSOL001S | L38: Solar PV - Utility with 2-hour storage | M38: Solar PV
B39: INR | C39: Indian Rupee | E39: LeastCost | F39: Scenario Name 2 (Less ambitious) | G39: - | K39: PWRWND001S | L39: Onshore wind with storage | M39: Onshore Wind
B40: JPY | C40: Japanese Yen | G40: - | K40: BESS | L40: Battery | M40: Other
G41: -
G42: -
G43: -
G44: -
G45: -

Sheet Visualisation Dashboard
A1: MINFin
A2: Visualisation Dashboard
A4: MINFin Projections
A33: Financing Needs Projections
AD37: Net Benefits
AD38: Year | AE38: 2025 | AF38: 2030 | AG38: 2035 | AH38: 2040 | AI38: 2045 | AJ38: 2050 | AK38: 2055 | AL38: 2060 | AM38: 2065
AD39: Net1 | AE39: {=TRANSPOSE('OSeMOSYS (Input)'!$AG$143:$AG$151)+TRANSPOSE('OSeMOSYS (Input)'!$AC$143:$AC$151)+TRANSPOSE('OSeMOSYS (Input)'!$Z$143:$Z$151)+TRANSPOSE('OSeMOSYS (Input)'!$AF$143:$AF$151)} -> -9.1619022 | AF39: 20.411886 | AG39: 57.943075 | AH39: 7.0658643 | AI39: -16.931267 | AJ39: 66.697634 | AK39: 170.8762 | AL39: 215.17897 | AM39: 300.19716
AD40: Net2 | AE40: {=TRANSPOSE('OSeMOSYS (Input)'!$AG$143:$AG$151)+TRANSPOSE('OSeMOSYS (Input)'!$AC$143:$AC$151)+TRANSPOSE('OSeMOSYS (Input)'!$Z$143:$Z$151)+TRANSPOSE('OSeMOSYS (Input)'!$AF$143:$AF$151)} -> -9.1619022 | AF40: 20.411886 | AG40: 57.943075 | AH40: 7.0658643 | AI40: -16.931267 | AJ40: 66.697634 | AK40: 170.8762 | AL40: 215.17897 | AM40: 300.19716
AD41: Pos1 | AE41: 1 | AF41: =AE42+1 -> 5 | AG41: =AF42+1 -> 9 | AH41: =AG42+1 -> 13 | AI41: =AH42+1 -> 17 | AJ41: =AI42+1 -> 21 | AK41: =AJ42+1 -> 25 | AL41: =AK42+1 -> 29 | AM41: =AL42+1 -> 33
AD42: Pos2 | AE42: =AE41+$AE$43 -> 4 | AF42: =AF41+$AE$43 -> 8 | AG42: =AG41+$AE$43 -> 12 | AH42: =AH41+$AE$43 -> 16 | AI42: =AI41+$AE$43 -> 20 | AJ42: =AJ41+$AE$43 -> 24 | AK42: =AK41+$AE$43 -> 28 | AL42: =AL41+$AE$43 -> 32 | AM42: =AM41+$AE$43 -> 36
AD43: Spacing | AE43: 3
E66: FFRM | F66: NZ Cost (Million US$)
E67: Coal | F67: =SUM('Investment Needs'!C172:AV172) -> 0
E68: Gas | F68: =SUM('Investment Needs'!C175:AV175) -> 0
E69: Oil | F69: =SUM('Investment Needs'!C178:AV178) -> 0
A87: Funding Availability Projections
A117: Historic Financing
M120: rank | N120: source | O120: vol | P120: market
M121: =5-RANK(P121,$P$121:$P$124) -> 2 | N121: Conc Dom | O121: =SUMIFS('Financing Baseline'!K49:K516,'Financing Baseline'!F49:F516,"Conc_DPS",'Financing Baseline'!G49:G516,"Loan") -> 205.98 | P121: {=IFERROR(SUMPRODUCT(IF('Financing Baseline'!F49:F516="Conc_DPS",1,0),IF('Financing Baseline'!G49:G516="Loan",1,0),'Financing Baseline'!K49:K516,'Financing Baseline'!X49:X516)/'Visualisation Dashboard'!O121,0)} -> 0.22868714
M122: =5-RANK(P122,$P$121:$P$124) -> 1 | N122: Conc Intl | O122: =SUMIFS('Financing Baseline'!K49:K516,'Financing Baseline'!F49:F516,"Conc_IFI",'Financing Baseline'!G49:G516,"Loan") -> 8033.9146 | P122: {=IFERROR( SUMPRODUCT(IF('Financing Baseline'!F49:F516="Conc_IFI",1,0),IF('Financing Baseline'!G49:G516="Loan",1,0),'Financing Baseline'!K49:K516,'Financing Baseline'!X49:X516)/ 'Visualisation Dashboard'!O122, 0)} -> 0.19386327
M123: =5-RANK(P123,$P$121:$P$124) -> 4 | N123: Com Dom | O123: =SUMIFS('Financing Baseline'!K49:K516,'Financing Baseline'!G49:G516,"Loan",'Financing Baseline'!F49:F516,"Comm_Dom") -> 51.4 | P123: {=IFERROR(SUMPRODUCT(IF('Financing Baseline'!F49:F516="Comm_Dom",1,0),IF('Financing Baseline'!G49:G516="Loan",1,0),'Financing Baseline'!K49:K516,'Financing Baseline'!X49:X516)/'Visualisation Dashboard'!O123,0)} -> 0.7523873
D124: Provider | E124: Instrument | F124: Origin | G124: Source | M124: =5-RANK(P124,$P$121:$P$124) -> 3 | N124: Com Intl | O124: =SUMIFS('Financing Baseline'!K49:K516,'Financing Baseline'!G49:G516,"Loan",'Financing Baseline'!F49:F516,"Comm_Intl") -> 484.02 | P124: {=IFERROR(SUMPRODUCT(IF('Financing Baseline'!F49:F516="Comm_Intl",1,0),IF('Financing Baseline'!G49:G516="Loan",1,0),'Financing Baseline'!K49:K516,'Financing Baseline'!X49:X516)/'Visualisation Dashboard'!O124,0)} -> 0.66103185
C125: 1 | D125: ='Financing Baseline'!L31 -> 0.86302412 | E125: ='Financing Baseline'!K16 -> 0.79897797 | F125: ='Financing Baseline'!L33 -> 0.13437369 | G125: ='High Level Dashboard'!F53 -> 0.74381344 | M125: =IFERROR(VLOOKUP(1,$M$121:$N$124,2,FALSE),"") -> Conc Intl | N125: =IFERROR(VLOOKUP(2,$M$121:$N$124,2,FALSE),"") -> Conc Dom | O125: =IFERROR(VLOOKUP(3,$M$121:$N$124,2,FALSE),"") -> Com Intl | P125: =IFERROR(VLOOKUP(4,$M$121:$N$124,2,FALSE),"") -> Com Dom
C126: 2 | D126: ='Financing Baseline'!L32 -> 0.13697588 | E126: ='Financing Baseline'!L16 -> 0.20102203 | F126: ='Financing Baseline'!L34 -> 0.86562631 | G126: ='High Level Dashboard'!F54 -> 0.11109827 | M126: =IFERROR(VLOOKUP(M125,$N$121:$O$124,2,FALSE),0) -> 8033.9146 | N126: =IFERROR(VLOOKUP(N125,$N$121:$O$124,2,FALSE),0) -> 205.98 | O126: =IFERROR(VLOOKUP(O125,$N$121:$O$124,2,FALSE),0) -> 484.02 | P126: =IFERROR(VLOOKUP(P125,$N$121:$O$124,2,FALSE),0) -> 51.4
C127: 3 | D127: 0 | E127: 0 | F127: 0 | G127: ='High Level Dashboard'!F55 -> 0.12181287 | L127: 0 | M127: =IFERROR(VLOOKUP(1,$M$121:$P$124,4,FALSE),"") -> 0.19386327
C128: 4 | D128: 0 | E128: 0 | F128: 0 | G128: ='High Level Dashboard'!F56 -> 0.02327542 | L128: =IFERROR(VLOOKUP(1,$M$121:$O$124,3,FALSE),0) -> 8033.9146 | M128: =IFERROR(VLOOKUP(1,$M$121:$P$124,4,FALSE),"") -> 0.19386327
L129: =IFERROR(VLOOKUP(1,$M$121:$O$124,3,FALSE),0) -> 8033.9146
L130: =IFERROR(VLOOKUP(1,$M$121:$O$124,3,FALSE),0) -> 8033.9146 | N130: =IFERROR(VLOOKUP(2,$M$121:$P$124,4,FALSE),"") -> 0.22868714
L131: =IFERROR(VLOOKUP(2,$M$121:$O$124,3,FALSE)+$L$128,0) -> 8239.8946 | N131: =IFERROR(VLOOKUP(2,$M$121:$P$124,4,FALSE),"") -> 0.22868714
L132: =IFERROR(VLOOKUP(2,$M$121:$O$124,3,FALSE)+$L$128,0) -> 8239.8946
L133: =IFERROR(VLOOKUP(2,$M$121:$O$124,3,FALSE)+$L$128,0) -> 8239.8946 | O133: =IFERROR(VLOOKUP(3,$M$121:$P$124,4,FALSE),"") -> 0.66103185
L134: =IFERROR(VLOOKUP(3,$M$121:$O$124,3,FALSE)+$L$131,0) -> 8723.9146 | O134: =IFERROR(VLOOKUP(3,$M$121:$P$124,4,FALSE),"") -> 0.66103185
L135: =IFERROR(VLOOKUP(3,$M$121:$O$124,3,FALSE)+$L$131,0) -> 8723.9146
L136: =IFERROR(VLOOKUP(3,$M$121:$O$124,3,FALSE)+$L$131,0) -> 8723.9146 | P136: =IFERROR(VLOOKUP(4,$M$121:$P$124,4,FALSE),"") -> 0.7523873
L137: =IFERROR(VLOOKUP(4,$M$121:$O$124,3,FALSE)+$L$134,0) -> 8775.3146 | P137: =IFERROR(VLOOKUP(4,$M$121:$P$124,4,FALSE),"") -> 0.7523873
D148: Financing Sources | AF148: WACC Calculation
C149: Conc IFI (Debt) | D149: ='Financing Baseline'!B32 -> 8033.9146 | AD149: Rank | AE149: Technology | AF149: IRR | AG149: Share of Equity | AH149: Interest Rate | AI149: Share of Debt | AJ149: Volume of Finance | AK149: WACC
C150: Conc DPS (Debt) | D150: ='Financing Baseline'!B33 -> 205.98 | AD150: =IFERROR(RANK($AK150,$AK$150:$AK$159,1)+COUNTIF(AK150:$AK$159,AK150)-1,"") -> 7 | AE150: {=IF(_xlfn.UNIQUE('Financing Baseline'!$C$49:$C$516)=0,"",_xlfn.UNIQUE('Financing Baseline'!$C$49:$C$516))} -> Geothermal | AF150: =IFERROR(AVERAGEIFS('Financing Baseline'!$P$49:$P$516, 'Financing Baseline'!$C$49:$C$516, AE150, 'Financing Baseline'!$G$49:$G$516, "Equity"),0) -> 0.18721296 | AG150: =IFERROR((SUMIFS('Financing Baseline'!$N$49:$N$516, 'Financing Baseline'!$C$49:$C$516, $AE150, 'Financing Baseline'!$G$49:$G$516, "Equity"))/$AJ150,0) -> 0.25579778 | AH150: =IFERROR(AVERAGEIFS('Financing Baseline'!$P$46:$P$513, 'Financing Baseline'!$C$46:$C$513, AE150, 'Financing Baseline'!$G$46:$G$513, "Loan"),0) -> 0.032753269 | AI150: =IFERROR(SUMIFS('Financing Baseline'!$N$49:$N$516, 'Financing Baseline'!$C$49:$C$516, AE150, 'Financing Baseline'!$G$49:$G$516, "Loan")/$AJ150,0) -> 0.74420222 | AJ150: =SUMIF('Financing Baseline'!$C$49:$C$516, AE150, 'Financing Baseline'!$N$49:$N$516) -> 4410.8409 | AK150: =IFERROR( (AF150*(AG150/(AG150+AI150)))+ (AH150*(AI150/(AG150+AI150))), "") -> 0.072263716
C151: Comm Intl (Debt) | D151: ='Financing Baseline'!B34 -> 484.02 | AD151: =IFERROR(RANK($AK151,$AK$150:$AK$159,1)+COUNTIF(AK151:$AK$159,AK151)-1,"") -> 3 | AE151: Solar | AF151: =IFERROR(AVERAGEIFS('Financing Baseline'!$P$49:$P$516, 'Financing Baseline'!$C$49:$C$516, AE151, 'Financing Baseline'!$G$49:$G$516, "Equity"),0) -> 0.053 | AG151: =IFERROR((SUMIFS('Financing Baseline'!$N$49:$N$516, 'Financing Baseline'!$C$49:$C$516, $AE151, 'Financing Baseline'!$G$49:$G$516, "Equity"))/$AJ151,0) -> 0.25080298 | AH151: =IFERROR(AVERAGEIFS('Financing Baseline'!$P$46:$P$513, 'Financing Baseline'!$C$46:$C$513, AE151, 'Financing Baseline'!$G$46:$G$513, "Loan"),0) -> 0.036277944 | AI151: =IFERROR(SUMIFS('Financing Baseline'!$N$49:$N$516, 'Financing Baseline'!$C$49:$C$516, AE151, 'Financing Baseline'!$G$49:$G$516, "Loan")/$AJ151,0) -> 0.74919702 | AJ151: =SUMIF('Financing Baseline'!$C$49:$C$516, AE151, 'Financing Baseline'!$N$49:$N$516) -> 783.025 | AK151: =IFERROR( (AF151*(AG151/(AG151+AI151)))+ (AH151*(AI151/(AG151+AI151))), "") -> 0.040471885
C152: Comm Dom (Debt) | D152: ='Financing Baseline'!B35 -> 51.4 | M152: Market Elements by Financier | T152: Market Elements by Financier | AD152: =IFERROR(RANK($AK152,$AK$150:$AK$159,1)+COUNTIF(AK152:$AK$159,AK152)-1,"") -> 8 | AE152: Biomass | AF152: =IFERROR(AVERAGEIFS('Financing Baseline'!$P$49:$P$516, 'Financing Baseline'!$C$49:$C$516, AE152, 'Financing Baseline'!$G$49:$G$516, "Equity"),0) -> 0.12 | AG152: =IFERROR((SUMIFS('Financing Baseline'!$N$49:$N$516, 'Financing Baseline'!$C$49:$C$516, $AE152, 'Financing Baseline'!$G$49:$G$516, "Equity"))/$AJ152,0) -> 0.38427948 | AH152: =IFERROR(AVERAGEIFS('Financing Baseline'!$P$46:$P$513, 'Financing Baseline'!$C$46:$C$513, AE152, 'Financing Baseline'!$G$46:$G$513, "Loan"),0) -> 0.06152105 | AI152: =IFERROR(SUMIFS('Financing Baseline'!$N$49:$N$516, 'Financing Baseline'!$C$49:$C$516, AE152, 'Financing Baseline'!$G$49:$G$516, "Loan")/$AJ152,0) -> 0.61572052 | AJ152: =SUMIF('Financing Baseline'!$C$49:$C$516, AE152, 'Financing Baseline'!$N$49:$N$516) -> 229 | AK152: =IFERROR( (AF152*(AG152/(AG152+AI152)))+ (AH152*(AI152/(AG152+AI152))), "") -> 0.08399331
...

Sheet Financial Instruments
A1: MINFin
A2: Financial Instruments
A4: Discount Rate Donor | B4: 0.04
A5: Discount Rate Recipient | B5: 0.0533
A7: ='High Level Dashboard'!A62 -> Scenario | B7: ='High Level Dashboard'!C62 -> Net Zero
B9: Total Over Modelling Period | C9: 2025 | D9: 2026 | E9: 2027 | F9: 2028 | G9: 2029 | H9: 2030 | I9: 2031 | J9: 2032 | K9: 2033 | L9: 2034 | M9: 2035 | N9: 2036 | O9: 2037 | P9: 2038 | Q9: 2039 | R9: 2040 | S9: 2041 | T9: 2042 | U9: 2043 | V9: 2044 | W9: 2045 | X9: 2046 | Y9: 2047 | Z9: 2048 | AA9: 2049 | AB9: 2050 | AC9: 2051 | AD9: 2052 | AE9: 2053 | AF9: 2054 | AG9: 2055 | AH9: 2056 | AI9: 2057 | AJ9: 2058 | AK9: 2059 | AL9: 2060 | AM9: 2061 | AN9: 2062 | AO9: 2063 | AP9: 2064 | AQ9: 2065 | AR9: 2066 | AS9: 2067 | AT9: 2068 | AU9: 2069 | AV9: 2070
A10: 1. Grants
A11: 1a. Undiscounted | B11: =SUM(C11:AV11) -> 829.8024 | C11: =C17 -> 300 | D11: =D17 -> 0 | E11: =E17 -> 40.8221 | F11: =F17 -> 8.4931 | G11: =G17 -> 9.2837 | H11: =H17 -> -63.3406 | I11: =I17 -> -167.113 | J11: =J17 -> 20.2359 | ... AV11: =AV17 -> 128.2393
A12: 1a. Donor | B12: =SUM(C12:AV12) -> -129.16168 | C12: =-C11/(1+$B$4)^(C$9-$C$9+1) -> -288.46154 | D12: =-D11/(1+$B$4)^(D$9-$C$9+1) -> 0 | E12: =-E11/(1+$B$4)^(E$9-$C$9+1) -> -36.290698 | F12: =-F11/(1+$B$4)^(F$9-$C$9+1) -> -7.2599375 | G12: =-G11/(1+$B$4)^(G$9-$C$9+1) -> -7.6305247 | H12: =-H11/(1+$B$4)^(H$9-$C$9+1) -> 50.058996 | I12: =-I11/(1+$B$4)^(I$9-$C$9+1) -> 126.99215 | J12: =-J11/(1+$B$4)^(J$9-$C$9+1) -> -14.786174 | ... AV12: =-AV11/(1+$B$4)^(AV$9-$C$9+1) -> -21.109966
A13: 1a. Recipient | B13: =SUM(C13:AV13) -> 88.846657 | C13: =C11/(1+$B$5)^(C$9-$C$9+1) -> 284.81914 | D13: =D11/(1+$B$5)^(D$9-$C$9+1) -> 0 | E13: =E11/(1+$B$5)^(E$9-$C$9+1) -> 34.933258 | F13: =F11/(1+$B$5)^(F$9-$C$9+1) -> 6.90014 | G13: =G11/(1+$B$5)^(G$9-$C$9+1) -> 7.1607857 | H13: =H11/(1+$B$5)^(H$9-$C$9+1) -> -46.384157 | I13: =I11/(1+$B$5)^(I$9-$C$9+1) -> -116.18382 | J13: =J11/(1+$B$5)^(J$9-$C$9+1) -> 13.356905 | ... AV13: =AV11/(1+$B$5)^(AV$9-$C$9+1) -> 11.765903
B14: =SUM(C17:AB17) -> -552.6454
A15: 1a - Without FF Savings
A16: Cumulative Grant Requirement (Million US$) | B16: =SUM(C17:AV17) -> 829.8024
A17: Annual Grant Requirement (Million US$) | C17: =SUM(C18:C21) -> 300 | D17: =SUM(D18:D21) -> 0 | E17: =SUM(E18:E21) -> 40.8221 | F17: =SUM(F18:F21) -> 8.4931 | G17: =SUM(G18:G21) -> 9.2837 | H17: =SUM(H18:H21) -> -63.3406 | I17: =SUM(I18:I21) -> -167.113 | J17: =SUM(J18:J21) -> 20.2359 | ... AV17: =SUM(AV18:AV21) -> 128.2393
A18: New Power Generation ($ Million) | C18: ='Investment Needs'!C12 -> 300 | D18: ='Investment Needs'!D12 -> 0 | E18: ='Investment Needs'!E12 -> 32.4531 | F18: ='Investment Needs'!F12 -> 0 | G18: ='Investment Needs'!G12 -> 0 | H18: ='Investment Needs'!H12 -> -56.4066 | I18: ='Investment Needs'!I12 -> -164.8087 | J18: ='Investment Needs'!J12 -> 23.3282 | ... AV18: ='Investment Needs'!AV12 -> 97.0504
A19: Stranded Power Generation ($ Million) | C19: {=TRANSPOSE('FFRM (Input)'!D9:D54)+TRANSPOSE('FFRM (Input)'!G9:G54)+TRANSPOSE('FFRM (Input)'!J9:J54)} -> 0 | D19: 0 | E19: 0 | F19: 0 | G19: 0 | H19: 0 | I19: 0 | J19: 0 | K19: 0 | L19: 0 | M19: 0 | N19: 0 | O19: 0 | P19: 0 | Q19: 0 | R19: 0 | S19: 0 | T19: 0 | U19: 0 | V19: 0 | W19: 0 | X19: 0 | Y19: 0 | Z19: 0 | AA19: 0 | AB19: 0 | AC19: 0 | AD19: 0 | AE19: 0 | AF19: 0 | AG19: 0 | AH19: 0 | AI19: 0 | AJ19: 0 | AK19: 0 | AL19: 0 | AM19: 0 | AN19: 0 | AO19: 0 | AP19: 0 | AQ19: 0 | AR19: 0 | AS19: 0 | AT19: 0 | AU19: 0 | AV19: 0
A20: Variable Cost ($ Million) | C20: {=(TRANSPOSE('OSeMOSYS (Input)'!D139:D184)-TRANSPOSE('OSeMOSYS (Input)'!E139:E184))-(TRANSPOSE('OSeMOSYS (Input)'!AN21:AN66)-TRANSPOSE('OSeMOSYS (Input)'!AN85:AN130))} -> 0 | D20: 0 | E20: 13.1888 | F20: 13.294 | G20: 14.0657 | H20: -10.4501 | I20: -6.4782 | J20: -6.582 | K20: -7.4456 | L20: -3.3494 | M20: 7.9877 | N20: 7.2762 | O20: 9.0172 | P20: 9.5765 | Q20: 10.6065 | R20: -3.8046 | S20: -3.3119 | T20: -3.9718 | U20: -0.1177 | V20: 1.6779 | W20: 2.3954 | X20: 4.0938 | Y20: -2.5669 | Z20: -9.0584 | AA20: -11.9149 | AB20: -26.5211 | AC20: -26.7989 | AD20: -16.3997 | AE20: 2.3588 | AF20: 3.3959 | AG20: 8.6545 | AH20: 12.4842 | AI20: 13.1178 | AJ20: 15.9512 | AK20: 18.7876 | AL20: 21.2555 | AM20: 25.9574 | AN20: 30.2909 | AO20: 33.5319 | AP20: 37.4442 | AQ20: 41.8637 | AR20: 46.1619 | AS20: 49.9377 | AT20: 53.9304 | AU20: 57.441 | AV20: 61.4528
A21: Fixed Cost ($ Million) | C21: {=TRANSPOSE('OSeMOSYS (Input)'!F139:F184)-TRANSPOSE('OSeMOSYS (Input)'!G139:G184)} -> 0 | D21: 0 | E21: -4.8198 | F21: -4.8009 | G21: -4.782 | H21: 3.5161 | I21: 4.1739 | J21: 3.4897 | K21: 7.5471 | L21: 4.4254 | M21: -1.1876 | N21: -1.5333 | O21: -2.3244 | P21: -1.3549 | Q21: -0.6722 | R21: 2.754 | S21: 1.6884 | T21: 2.503 | U21: 1.411 | V21: 0.9583 | W21: 0.6896 | X21: 0.0473 | Y21: 1.025 | Z21: 3.992 | AA21: 5.0913 | AB21: 16.1775 | AC21: 20.3635 | AD21: 15.8004 | AE21: 6.1335 | AF21: 3.4804 | AG21: -0.6052 | AH21: -1.4916 | AI21: -2.165 | AJ21: -3.6073 | AK21: -5.1275 | AL21: -8.8193 | AM21: -10.5586 | AN21: -12.8217 | AO21: -14.293 | AP21: -16.5002 | AQ21: -19.3835 | AR21: -22.2029 | AS21: -24.2338 | AT21: -26.6588 | AU21: -28.399 | AV21: -30.2639
A23: 1b - With FF Savings
A24: Cumulative Grant Requirement Considering FF Savings (Million US$) | B24: =SUM(C25:AV25) -> -946.7667
A25: Annual Grant Requirement Considering FF Savings(Million US$) | C25: =C17-C26 -> 300 | D25: =D17-D26 -> 0 | E25: =E17-E26 -> 45.4373 | F25: =F17-F26 -> 13.003 | G25: =G17-G26 -> 12.875 | H25: =H17-H26 -> -65.97 | I25: =I17-I26 -> -169.0689 | J25: =J17-J26 -> 17.7666 | ... AV25: =AV17-AV26 -> -24.3048
A26: Fossil Fuel Savings (Million US$) | C26: {=TRANSPOSE('OSeMOSYS (Input)'!AN85:AN130)-TRANSPOSE('OSeMOSYS (Input)'!AN21:AN66)} -> 0 | D26: 0 | E26: -4.6152 | F26: -4.5099 | G26: -3.5913 | H26: 2.6294 | I26: 1.9559 | J26: 2.4693 | K26: 9.7175 | L26: 3.7868 | M26: 6.1791 | N26: 3.7812 | O26: 5.2467 | P26: 5.8192 | Q26: 7.9206 | R26: 5.5285 | S26: 6.678 | T26: 8.8512 | U26: 7.9744 | V26: 7.9916 | W26: 8.8247 | X26: 8.4078 | Y26: 6.9456 | Z26: 12.4458 | AA26: 14.673 | AB26: 25.6271 | AC26: 21.3545 | AD26: 22.676 | AE26: 26.0347 | AF26: 30.4391 | AG26: 34.9411 | AH26: 43.3815 | AI26: 52.6015 | AJ26: 59.5598 | AK26: 67.4945 | AL26: 76.245 | AM26: 84.4713 | AN26: 93.6008 | AO26: 103.1902 | AP26: 111.2738 | AQ26: 116.1024 | AR26: 121.4919 | AS26: 129.0093 | AT26: 135.4324 | AU26: 143.9882 | AV26: 152.5441
A28: 1c - With FF and Carbon Savings
A29: Cumulative Grant Requirement Considering FF and Carbon Savings (Million US$) | B29: =SUM(C30:AB30) -> -981.40209
A30: Annual Grant Requirement Considering FF and Carbon Savings(Million US$) | C30: =C25-C31 -> 300 | D30: =D25-D31 -> 0 | E30: =E25-E31 -> 48.66236 | F30: =F25-F31 -> 16.22905 | G30: =G25-G31 -> 15.49914 | H30: =H25-H31 -> -67.9275 | I30: =I25-I31 -> -170.33429 | J30: =J25-J31 -> 16.174877 | ... AV30: =AV25-AV31 -> -370.97378
A31: Carbon Savings (Million US$) | C31: {=(TRANSPOSE('OSeMOSYS (Input)'!S139:S184)-TRANSPOSE('OSeMOSYS (Input)'!R139:R184))*C32:AV32} -> 0 | D31: 0 | E31: -3.22506 | F31: -3.22605 | G31: -2.62414 | H31: 1.9575 | I31: 1.265385 | J31: 1.591723 | K31: 12.059072 | L31: 2.443004 | M31: 3.629839 | N31: 1.997043 | O31: 6.22244 | P31: 8.396457 | Q31: 9.749432 | R31: 8.600742 | S31: 9.46504 | T31: 10.95081 | U31: 10.657024 | V31: 10.875942 | W31: 11.57156 | X31: 11.531439 | Y31: 10.827572 | Z31: 32.01484 | AA31: 41.560426 | AB31: 79.727648 | AC31: 81.25593 | AD31: 86.38616 | AE31: 93.001696 | AF31: 100.54019 | AG31: 108.44149 | AH31: 120.04062 | AI31: 132.93072 | AJ31: 146.73411 | AK31: 162.55103 | AL31: 178.33476 | AM31: 193.33542 | AN31: 210.80923 | AO31: 229.97982 | AP31: 246.52291 | AQ31: 257.58318 | AR31: 270.18453 | AS31: 288.10435 | AT31: 304.22264 | AU31: 325.05268 | AV31: 346.66898
A32: Carbon Price ($/Ton CO2e) | C32: 67.06 | D32: 68.57 | E32: 70.11 | F32: 71.69 | G32: 73.3 | H32: 75 | I32: 76.69 | J32: 78.41 | K32: 80.18 | L32: 81.98 | M32: 83.83 | N32: 85.71 | O32: 87.64 | P32: 89.61 | Q32: 91.63 | R32: 93.69 | S32: 95.8 | T32: 97.95 | U32: 100.16 | V32: 102.41 | W32: 104.72 | X32: 107.07 | Y32: 109.48 | Z32: 111.94 | AA32: 114.46 | AB32: 117.04 | AC32: 119.67 | AD32: 122.36 | AE32: 125.12 | AF32: 127.93 | AG32: 130.81 | AH32: 133.75 | AI32: 136.76 | AJ32: 139.84 | AK32: 142.99 | AL32: 146.2 | AM32: 149.49 | AN32: 152.86 | AO32: 156.3 | AP32: 159.81 | AQ32: 163.41 | AR32: 167.09 | AS32: 170.85 | AT32: 174.69 | AU32: 178.62 | AV32: 182.64
A35: 2. Loans
A36: 2b. Undiscounted | B36: =SUM(C36:AV36) -> 5107.4668 | C36: =C50 -> -300 | D36: =D50 -> 0 | E36: =E50 -> -48.66236 | F36: =F50 -> -16.22905 | G36: =G50 -> -15.49914 | H36: =H50 -> 67.9275 | I36: =I50 -> 170.33429 | J36: =J50 -> -16.174877 | ... AV36: =AV50 -> 370.97378
A37: 2b. Donor | B37: =SUM(C37:AV37) -> 1273.4388 | C37: =C36/(1+$B$4)^(C$9-$C$9+1) -> -288.46154 | D37: =D36/(1+$B$4)^(D$9-$C$9+1) -> 0 | E37: =E36/(1+$B$4)^(E$9-$C$9+1) -> -43.260661 | F37: =F36/(1+$B$4)^(F$9-$C$9+1) -> -13.87266 | G37: =G36/(1+$B$4)^(G$9-$C$9+1) -> -12.739163 | H37: =H36/(1+$B$4)^(H$9-$C$9+1) -> 53.68409 | I37: =I36/(1+$B$4)^(I$9-$C$9+1) -> 129.44006 | J37: =J36/(1+$B$4)^(J$9-$C$9+1) -> -11.818824 | ... AV37: =AV36/(1+$B$4)^(AV$9-$C$9+1) -> 61.067426
A38: 2b. Recipient | B38: =SUM(C38:AV38) -> -807.57032 | C38: =(C17+(-C45-C51))/(1+$B$5)^(C$9-$C$9+1) -> 284.81914 | D38: =(D17+(-D45-D51))/(1+$B$5)^(D$9-$C$9+1) -> 0 | E38: =(E17+(-E45-E51))/(1+$B$5)^(E$9-$C$9+1) -> 41.642512 | F38: =(F17+(-F45-F51))/(1+$B$5)^(F$9-$C$9+1) -> 13.18514 | G38: =(G17+(-G45-G51))/(1+$B$5)^(G$9-$C$9+1) -> 11.954934 | H38: =(H17+(-H45-H51))/(1+$B$5)^(H$9-$C$9+1) -> -49.743132 | I38: =(I17+(-I45-I51))/(1+$B$5)^(I$9-$C$9+1) -> -118.42339 | J38: =(J17+(-J45-J51))/(1+$B$5)^(J$9-$C$9+1) -> 10.676387 | ... AV38: =(AV17+(-AV45-AV51))/(1+$B$5)^(AV$9-$C$9+1) -> -34.036692
A40: 2a - With Fossil Fuel Savings
A41: Donor MIRR | B41: =MIRR(C43:AV43,B4,B4) -> 0.049177004
A42: Recipient MIRR | B42: =MIRR(C43:AV43,B5,B5) -> 0.060301381
A43: Net Cashflow (Million US$) | B43: =SUM(C43:AV43) -> 946.7667 | C43: =SUM(C44:C45) -> -300 | D43: =SUM(D44:D45) -> 0 | E43: =SUM(E44:E45) -> -45.4373 | F43: =SUM(F44:F45) -> -13.003 | G43: =SUM(G44:G45) -> -12.875 | H43: =SUM(H44:H45) -> 65.97 | I43: =SUM(I44:I45) -> 169.0689 | J43: =SUM(J44:J45) -> -17.7666 | ... AV43: =SUM(AV44:AV45) -> 24.3048
A44: Incremental Investment Needs Total (Million US$) | B44: =SUM(C44:AV44) -> -829.8024 | C44: =-C17 -> -300 | D44: =-D17 -> 0 | E44: =-E17 -> -40.8221 | F44: =-F17 -> -8.4931 | G44: =-G17 -> -9.2837 | H44: =-H17 -> 63.3406 | I44: =-I17 -> 167.113 | J44: =-J17 -> -20.2359 | ... AV44: =-AV17 -> -128.2393
A45: Delta Fossil Fuel Savings (Million US$) | B45: =SUM(C45:AV45) -> 1776.5691 | C45: {=TRANSPOSE('OSeMOSYS (Input)'!AN85:AN130)-TRANSPOSE('OSeMOSYS (Input)'!AN21:AN66)} -> 0 | D45: 0 | E45: -4.6152 | F45: -4.5099 | G45: -3.5913 | H45: 2.6294 | I45: 1.9559 | J45: 2.4693 | K45: 9.7175 | L45: 3.7868 | M45: 6.1791 | N45: 3.7812 | O45: 5.2467 | P45: 5.8192 | Q45: 7.9206 | R45: 5.5285 | S45: 6.678 | T45: 8.8512 | U45: 7.9744 | V45: 7.9916 | W45: 8.8247 | X45: 8.4078 | Y45: 6.9456 | Z45: 12.4458 | AA45: 14.673 | AB45: 25.6271 | AC45: 21.3545 | AD45: 22.676 | AE45: 26.0347 | AF45: 30.4391 | AG45: 34.9411 | AH45: 43.3815 | AI45: 52.6015 | AJ45: 59.5598 | AK45: 67.4945 | AL45: 76.245 | AM45: 84.4713 | AN45: 93.6008 | AO45: 103.1902 | AP45: 111.2738 | AQ45: 116.1024 | AR45: 121.4919 | AS45: 129.0093 | AT45: 135.4324 | AU45: 143.9882 | AV45: 152.5441
A47: 2b - With Fossil Fuel and Carbon Savings
A48: Donor MIRR | B48: =MIRR(C50:AV50,B4,B4) -> 0.071125271
A49: Recipient MIRR | B49: =MIRR(C50:AV50,B5,B5) -> 0.078381596
...

Sheet High Level Dashboard
A1: MINFin
A2: High-Level Dashboard
A4: Levers
A5: Currency: | B5: Foreign Currency | C5: Future | F5: Historic
A6: Currency Name: | B6: =VLOOKUP($B$5,'Financing Baseline'!$A$38:$C$39,3,FALSE) -> USD | C6: Debt | D6: Equity | E6: Total | F6: Debt | G6: Equity | H6: Total
A7: Financing requirements
A8: Concessional International Finance (Conc IFI)
A9: Debt : Equity Share | C9: =F9 -> 0.98341154 | D9: =G9 -> 0.016588463 | E9: =SUM(C9:D9) -> 1 | F9: ='Financing Baseline'!K17 -> 0.98341154 | G9: ='Financing Baseline'!L17 -> 0.016588463 | H9: =SUM(F9:G9) -> 1
A10: Average interest rate | C10: =F10 -> 0.022210933 | D10: =G10 -> 0.15093032 | E10: =IFERROR(($C$9*C10)+($D$9*D10),"") -> 0.02434619 | F10: ='Financing Baseline'!C32 -> 0.022210933 | G10: ='Financing Baseline'!C24 -> 0.15093032 | H10: =IFERROR(($F$9*F10)+($G$9*G10),"") -> 0.02434619
A11: Average grace period (years) | C11: =F11 -> 6.9218762 | D11: =G11 -> 0 | E11: =IFERROR(($C$9*C11)+($D$9*D11),"") -> 6.8070529 | F11: ='Financing Baseline'!E32 -> 6.9218762 | G11: ='Financing Baseline'!E24 -> 0 | H11: =IFERROR(($F$9*F11)+($G$9*G11),"") -> 6.8070529
A12: Average term of loan (years) | C12: =F12 -> 27.250361 | D12: =G12 -> 24.8871 | E12: =IFERROR(($C$9*C12)+($D$9*D12),"") -> 27.211158 | F12: ='Financing Baseline'!D32 -> 27.250361 | G12: ='Financing Baseline'!D24 -> 24.8871 | H12: =IFERROR(($F$9*F12)+($G$9*G12),"") -> 27.211158
A13: Average grant element | C13: =F13 -> 0.80599981 | D13: - | E13: - | F13: ='Financing Baseline'!J32 -> 0.80599981 | G13: - | H13: -
A14: Concessional Domestic Finance (Conc DPS)
A15: Debt : Equity Share | C15: =F15 -> 0.16880677 | D15: =G15 -> 0.83119323 | E15: =SUM(C15:D15) -> 1 | F15: ='Financing Baseline'!K18 -> 0.16880677 | G15: ='Financing Baseline'!L18 -> 0.83119323 | H15: =SUM(F15:G15) -> 1
A16: Average interest rate | C16: =F16 -> 0.026511348 | D16: =G16 -> 0.19684646 | E16: =IFERROR(($C$15*C16)+($D$15*D16),"") -> 0.16809274 | F16: ='Financing Baseline'!C33 -> 0.026511348 | G16: ='Financing Baseline'!C25 -> 0.19684646 | H16: =IFERROR(($F$15*F16)+($G$15*G16),"") -> 0.16809274
A17: Average grace period (years) | C17: =F17 -> 7.0987911 | D17: =G17 -> 0 | E17: =IFERROR(($C$15*C17)+($D$15*D17),"") -> 1.198324 | F17: ='Financing Baseline'!E33 -> 7.0987911 | G17: ='Financing Baseline'!E25 -> 0 | H17: =IFERROR(($F$15*F17)+($G$15*G17),"") -> 1.198324
A18: Average term of loan (years) | C18: =F18 -> 22.641732 | D18: =G18 -> 34.037672 | E18: =IFERROR(($C$15*C18)+($D$15*D18),"") -> 32.11396 | F18: ='Financing Baseline'!D33 -> 22.641732 | G18: ='Financing Baseline'!D25 -> 34.037672 | H18: =IFERROR(($F$15*F18)+($G$15*G18),"") -> 32.11396
A19: Average grant element | C19: =F19 -> 0.77131286 | D19: - | E19: - | F19: ='Financing Baseline'!J33 -> 0.77131286 | G19: - | H19: -
A20: Commercial International Finance (Comm Intl)
A21: Debt : Equity Share | C21: =F21 -> 0.36177808 | D21: =G21 -> 0.63822192 | E21: =SUM(C21:D21) -> 1 | F21: ='Financing Baseline'!K19 -> 0.36177808 | G21: ='Financing Baseline'!L19 -> 0.63822192 | H21: =SUM(F21:G21) -> 1
A22: Average interest rate | C22: =F22 -> 0.097008589 | D22: =G22 -> 0.11526586 | E22: =IFERROR(($C$21*C22)+($D$21*D22),"") -> 0.10866078 | F22: ='Financing Baseline'!C34 -> 0.097008589 | G22: ='Financing Baseline'!C26 -> 0.11526586 | H22: =IFERROR(($F$21*F22)+($G$21*G22),"") -> 0.10866078
A23: Average grace period (years) | C23: =F23 -> 2.8170943 | D23: =G23 -> 0 | E23: =IFERROR(($C$21*C23)+($D$21*D23),"") -> 1.019163 | F23: ='Financing Baseline'!E34 -> 2.8170943 | G23: ='Financing Baseline'!E26 -> 0 | H23: =IFERROR(($F$21*F23)+($G$21*G23),"") -> 1.019163
A24: Average term of loan (years) | C24: =F24 -> 15.774761 | D24: =G24 -> 25.574665 | E24: =IFERROR(($C$21*C24)+($D$21*D24),"") -> 22.029274 | F24: ='Financing Baseline'!D34 -> 15.774761 | G24: ='Financing Baseline'!D26 -> 25.574665 | H24: =IFERROR(($F$21*F24)+($G$21*G24),"") -> 22.029274
A25: Average grant element | C25: =F25 -> 0.33896815 | D25: - | E25: - | F25: ='Financing Baseline'!J34 -> 0.33896815 | G25: - | H25: -
A26: Commercial Domestic Finance (Comm Dom)
A27: Debt : Equity Share | C27: =F27 -> 0.20106557 | D27: =G27 -> 0.79893443 | E27: =SUM(C27:D27) -> 1 | F27: ='Financing Baseline'!K20 -> 0.20106557 | G27: ='Financing Baseline'!L20 -> 0.79893443 | H27: =SUM(F27:G27) -> 1
A28: Average interest rate | C28: =F28 -> 0.15091335 | D28: =G28 -> 0.14018787 | E28: =IFERROR(($C$27*C28)+($D$27*D28),"") -> 0.14234439 | F28: ='Financing Baseline'!C35 -> 0.15091335 | G28: ='Financing Baseline'!C27 -> 0.14018787 | H28: =IFERROR(($F$27*F28)+($G$27*G28),"") -> 0.14234439
A29: Average grace period (years) | C29: =F29 -> 7.5194553 | D29: =G29 -> 0 | E29: =IFERROR(($C$27*C29)+($D$27*D29),"") -> 1.5119036 | F29: ='Financing Baseline'!E35 -> 7.5194553 | G29: ='Financing Baseline'!E27 -> 0 | H29: =IFERROR(($F$27*F29)+($G$27*G29),"") -> 1.5119036
A30: Average term of loan (years) | C30: =F30 -> 18.540856 | D30: =G30 -> 30.214505 | E30: =IFERROR(($C$27*C30)+($D$27*D30),"") -> 27.867336 | F30: ='Financing Baseline'!D35 -> 18.540856 | G30: ='Financing Baseline'!D27 -> 30.214505 | H30: =IFERROR(($F$27*F30)+($G$27*G30),"") -> 27.867336
A31: Average grant element | C31: =F31 -> 0.2476127 | D31: - | E31: - | F31: ='Financing Baseline'!J35 -> 0.2476127 | G31: - | H31: -
A32: Average
A33: Debt : Equity Share | C33: =(C9*$C$53)+(C15*$C$54)+(C21*$C$55)+(C27*$C$56) -> 0.79897797 | D33: =(D9*$C$53)+(D15*$C$54)+(D21*$C$55)+(D27*$C$56) -> 0.20102203 | E33: =SUM(C33:D33) -> 1 | F33: ='Financing Baseline'!K16 -> 0.79897797 | G33: ='Financing Baseline'!L16 -> 0.20102203 | H33: =SUM(F33:G33) -> 1
A34: Average interest rate | C34: =((C10*C$9*$C$53)+(C16*C$15*$C$54)+(C22*C$21*$C$55)+(C28*C$27*$C$56))/((C$9*$C$53)+(C$15*$C$54)+(C$21*$C$55)+(C$27*$C$56)) -> 0.027191343 | D34: =((D10*D$9*$C$53)+(D16*D$15*$C$54)+(D22*D$21*$C$55)+(D28*D$27*$C$56))/((D$9*$C$53)+(D$15*$C$54)+(D$21*$C$55)+(D$27*$C$56)) -> 0.15723629 | E34: =IFERROR(($C$33*C34)+($D$33*D34),"") -> 0.053333243 | F34: ='Financing Baseline'!C31 -> 0.027191343 | G34: ='Financing Baseline'!C23 -> 0.15723629 | H34: =IFERROR(($F$33*F34)+($G$33*G34),"") -> 0.053333243
A35: Average grace period (years) | C35: =((C11*C$9*$C$53)+(C17*C$15*$C$54)+(C23*C$21*$C$55)+(C29*C$27*$C$56))/((C$9*$C$53)+(C$15*$C$54)+(C$21*$C$55)+(C$27*$C$56)) -> 6.7031217 | D35: =((D11*D$9*$C$53)+(D17*D$15*$C$54)+(D23*D$21*$C$55)+(D29*D$27*$C$56))/((D$9*$C$53)+(D$15*$C$54)+(D$21*$C$55)+(D$27*$C$56)) -> 0 | E35: =IFERROR(($C$33*C35)+($D$33*D35),"") -> 5.3556465 | F35: ='Financing Baseline'!E31 -> 6.7031217 | G35: ='Financing Baseline'!E23 -> 0 | H35: =IFERROR(($F$33*F35)+($G$33*G35),"") -> 5.3556465
A36: Average term of loan (years) | C36: =((C12*C$9*$C$53)+(C18*C$15*$C$54)+(C24*C$21*$C$55)+(C30*C$27*$C$56))/((C$9*$C$53)+(C$15*$C$54)+(C$21*$C$55)+(C$27*$C$56)) -> 26.45821 | D36: =((D12*D$9*$C$53)+(D18*D$15*$C$54)+(D24*D$21*$C$55)+(D30*D$27*$C$56))/((D$9*$C$53)+(D$15*$C$54)+(D$21*$C$55)+(D$27*$C$56)) -> 29.849349 | E36: =IFERROR(($C$33*C36)+($D$33*D36),"") -> 27.139904 | F36: ='Financing Baseline'!D31 -> 26.45821 | G36: ='Financing Baseline'!D23 -> 29.849349 | H36: =IFERROR(($F$33*F36)+($G$33*G36),"") -> 27.139904
A37: Average grant element | C37: =((C13*C$9*$C$53)+(C19*C$15*$C$54)+(C25*C$21*$C$55)+(C31*C$27*$C$56))/((C$9*$C$53)+(C$15*$C$54)+(C$21*$C$55)+(C$27*$C$56)) -> 0.77615489 | D37: - | E37: - | F37: ='Financing Baseline'!J31 -> 0.77615489 | G37: - | H37: -
A38: Funding availability
A39: CAGR of government spending | C39: ='Funding Baseline'!B6 -> -0.017285258 | F39: ='Funding Baseline'!B6 -> -0.017285258
A40: CAGR of international grants | C40: ='Funding Baseline'!B8 -> -1 | F40: ='Funding Baseline'!B8 -> -1
A41: SOE
...

Sheet Financing Baseline
A1: MINFin
A2: Financing Baseline
A4: FORWARD LOOKING PARAMETERS FOR FINANCING SOURCES
A5: Repayment Currency | B5: ='High Level Dashboard'!B5 -> Foreign Currency
A6: Exchange Rate Projections | B6: ='High Level Dashboard'!B6 -> USD
A7: ="Currency Contribution "&'Financing Baseline'!A38&" (%)" -> Currency Contribution Foreign Currency (%) | B7: =SUMIFS($K$49:$K$329,$L$49:$L$329,$C$38)/SUM($K$49:$K$329) -> 1
A8: ="Currency Contribution "&'Financing Baseline'!A39&" (%)" -> Currency Contribution Local Currency (%) | B8: =SUMIFS(K49:K329,L49:L329,"<>"&$C$38)/SUM(K49:K329) -> 0
A9: Current Year | B9: 2024
A10: Discount Rate | B10: ='High Level Dashboard'!E34 -> 0.053333243
A11: Discount rate for calcualtion of grant element | B11: =IFERROR(_xlfn.MAXIFS(P49:P496,G49:G496,"Loan"),10%) -> 0.18
A12: Annual Loan Payments | B12: 1
B14: Weighted Average | K14: Debt Equity Split
B15: ="Volume ("&$B$6&")" -> Volume (USD) | C15: Interest rate | D15: Term of loan | E15: Years of grace | F15: Average Annual Payment | G15: Average Annual Discounted Payment | H15: Total Discounted Payment | K15: Debt | L15: Equity
A16: Total financing volumes | B16: =SUM(B17:B20) -> 10983.175 | C16: =IFERROR(SUMPRODUCT(B17:B20,C17:C20)/SUM(B17:B20), 0) -> 0.053333243 | D16: =IFERROR(SUMPRODUCT(D17:D20,B17:B20)/SUM(B17:B20), 0) -> 27.139904 | E16: =IFERROR(SUMPRODUCT(B17:B20,E17:E20)/SUM(B17:B20),0) -> 5.3556465 | F16: =IFERROR(SUMPRODUCT(B17:B20,F17:F20)/SUM(B17:B20),0) -> 10.025427 | G16: =IFERROR(SUMPRODUCT(B17:B20,G17:G20)/SUM(B17:B20),0) -> 7.6477055 | H16: =IFERROR(SUMPRODUCT(B17:B20,H17:H20)/SUM(B17:B20),0) -> 191.60971 | K16: =IFERROR(SUMPRODUCT(K17:K20,B17:B20)/SUM(B17:B20),0) -> 0.79897797 | L16: =1-K16 -> 0.20102203
A17: Concessional International Finance (Conc IFI) | B17: =IF($B$5="Local Currency",SUMIF(F49:F516, "Conc_IFI", M49:M516),SUMIF(F49:F516, "Conc_IFI", IF($B$5="Local Currency",M49:M516,N49:N516))) -> 8169.4329 | C17: {=IFERROR(SUMPRODUCT(IF($F$49:$F$516="Conc_IFI",1,0),IF($B$5="Local Currency",M49:M516,N49:N516),P49:P516)/SUMPRODUCT(IF($F$49:$F$516="Conc_IFI",1,0),IF($B$5="Local Currency",M49:M516,N49:N516)), 0)} -> 0.02434619 | D17: {=IFERROR(SUMPRODUCT(IF($F$49:$F$516="Conc_IFI",1,0),IF($B$5="Local Currency",M49:M516,N49:N516),Q49:Q516)/SUMPRODUCT(IF($F$49:$F$516="Conc_IFI",1,0),IF($B$5="Local Currency",M49:M516,N49:N516)), 0)} -> 27.211158 | E17: {=IFERROR(SUMPRODUCT(IF($F$49:$F$516="Conc_IFI",1,0),IF($B$5="Local Currency",M49:M516,N49:N516),S49:S516)/SUMPRODUCT(IF($F$49:$F$516="Conc_IFI",1,0),IF($B$5="Local Currency",M49:M516,N49:N516)), 0)} -> 6.8070529 | F17: {=IFERROR(SUMPRODUCT(IF($F$49:$F$516="Conc_IFI",1,0),IF($B$5="Local Currency",M49:M516,N49:N516),U49:U516)/SUMPRODUCT(IF($F$49:$F$516="Conc_IFI",1,0),IF($B$5="Local Currency",M49:M516,N49:N516)), 0)} -> 8.8318947 | G17: {=IFERROR(SUMPRODUCT(IF($F$49:$F$516="Conc_IFI",1,0),IF($B$5="Local Currency",M49:M516,N49:N516),V49:V516)/SUMPRODUCT(IF($F$49:$F$516="Conc_IFI",1,0),IF($B$5="Local Currency",M49:M516,N49:N516)), 0)} -> 6.6343905 | H17: {=IFERROR(SUMPRODUCT(IF($F$49:$F$516="Conc_IFI",1,0),IF($B$5="Local Currency",M49:M516,N49:N516),W49:W516)/SUMPRODUCT(IF($F$49:$F$516="Conc_IFI",1,0),IF($B$5="Local Currency",M49:M516,N49:N516)), 0)} -> 166.60805 | K17: =IFERROR(SUMIFS($N$49:$N$496,$F$49:$F$496,"Conc_IFI",$G$49:$G$496,"Loan")/SUMIF($F$49:$F$496,"Conc_IFI",$N$49:$N$496),0) -> 0.98341154 | L17: =1-K17 -> 0.016588463
A18: Concessional Domestic Finance (Conc DPS) | B18: =IF($B$5="Local Currency",SUMIF(F49:F516,"Conc_DPS",M49:M516),SUMIF(F49:F516,"Conc_DPS",IF($B$5="Local Currency",M49:M516,N49:N516))) -> 1220.2117 | C18: {=IFERROR(SUMPRODUCT(IF($F$49:$F$516="Conc_DPS",1,0),IF($B$5="Local Currency",M49:M516,N49:N516),P49:P516)/SUMPRODUCT(IF($F$49:$F$516="Conc_DPS",1,0),IF($B$5="Local Currency",M49:M516,N49:N516)), 0)} -> 0.16809274 | D18: {=IFERROR(SUMPRODUCT(IF($F$49:$F$516="Conc_DPS",1,0),IF($B$5="Local Currency",M49:M516,N49:N516),Q49:Q516)/SUMPRODUCT(IF($F$49:$F$516="Conc_DPS",1,0),IF($B$5="Local Currency",M49:M516,N49:N516)), 0)} -> 32.11396 | E18: {=IFERROR(SUMPRODUCT(IF($F$49:$F$516="Conc_DPS",1,0),IF($B$5="Local Currency",M49:M516,N49:N516),S49:S516)/SUMPRODUCT(IF($F$49:$F$516="Conc_DPS",1,0),IF($B$5="Local Currency",M49:M516,N49:N516)), 0)} -> 1.198324 | F18: {=IFERROR(SUMPRODUCT(IF($F$49:$F$516="Conc_DPS",1,0),IF($B$5="Local Currency",M49:M516,N49:N516),U49:U516)/SUMPRODUCT(IF($F$49:$F$516="Conc_DPS",1,0),IF($B$5="Local Currency",M49:M516,N49:N516)), 0)} -> 21.692611 | G18: {=IFERROR(SUMPRODUCT(IF($F$49:$F$516="Conc_DPS",1,0),IF($B$5="Local Currency",M49:M516,N49:N516),V49:V516)/SUMPRODUCT(IF($F$49:$F$516="Conc_DPS",1,0),IF($B$5="Local Currency",M49:M516,N49:N516)), 0)} -> 16.96321 | H18: {=IFERROR(SUMPRODUCT(IF($F$49:$F$516="Conc_DPS",1,0),IF($B$5="Local Currency",M49:M516,N49:N516),W49:W516)/SUMPRODUCT(IF($F$49:$F$516="Conc_DPS",1,0),IF($B$5="Local Currency",M49:M516,N49:N516)), 0)} -> 446.09483 | K18: =IFERROR(SUMIFS($N$49:$N$496,$F$49:$F$496,"Conc_DPS",$G$49:$G$496,"Loan")/SUMIF($F$49:$F$496,"Conc_DPS",$N$49:$N$496),0) -> 0.16880677 | L18: =1-K18 -> 0.83119323
A19: Commercial International Finance (Comm Intl) | B19: =IF($B$5="Local Currency",SUMIF(F49:F516,"Comm_Intl",M49:M516),SUMIF(F49:F516,"Comm_Intl",IF($B$5="Local Currency",M49:M516,N49:N516))) -> 1337.892 | C19: {=IFERROR(SUMPRODUCT(IF($F$49:$F$516="Comm_Intl",1,0),IF($B$5="Local Currency",M49:M516,N49:N516),P49:P516)/SUMPRODUCT(IF($F$49:$F$516="Comm_Intl",1,0),IF($B$5="Local Currency",M49:M516,N49:N516)), 0)} -> 0.10866078 | D19: {=IFERROR(SUMPRODUCT(IF($F$49:$F$516="Comm_Intl",1,0),IF($B$5="Local Currency",M49:M516,N49:N516),Q49:Q516)/SUMPRODUCT(IF($F$49:$F$516="Comm_Intl",1,0),IF($B$5="Local Currency",M49:M516,N49:N516)), 0)} -> 22.029274 | E19: {=IFERROR(SUMPRODUCT(IF($F$49:$F$516="Comm_Intl",1,0),IF($B$5="Local Currency",M49:M516,N49:N516),S49:S516)/SUMPRODUCT(IF($F$49:$F$516="Comm_Intl",1,0),IF($B$5="Local Currency",M49:M516,N49:N516)), 0)} -> 1.019163 | F19: {=IFERROR(SUMPRODUCT(IF($F$49:$F$516="Comm_Intl",1,0),IF($B$5="Local Currency",M49:M516,N49:N516),U49:U516)/SUMPRODUCT(IF($F$49:$F$516="Comm_Intl",1,0),IF($B$5="Local Currency",M49:M516,N49:N516)), 0)} -> 7.0831867 | G19: {=IFERROR(SUMPRODUCT(IF($F$49:$F$516="Comm_Intl",1,0),IF($B$5="Local Currency",M49:M516,N49:N516),V49:V516)/SUMPRODUCT(IF($F$49:$F$516="Comm_Intl",1,0),IF($B$5="Local Currency",M49:M516,N49:N516)), 0)} -> 5.7902261 | H19: {=IFERROR(SUMPRODUCT(IF($F$49:$F$516="Comm_Intl",1,0),IF($B$5="Local Currency",M49:M516,N49:N516),W49:W516)/SUMPRODUCT(IF($F$49:$F$516="Comm_Intl",1,0),IF($B$5="Local Currency",M49:M516,N49:N516)), 0)} -> 123.00436 | K19: =IFERROR(SUMIFS($N$49:$N$496,$F$49:$F$496,"Comm_Intl",$G$49:$G$496,"Loan")/SUMIF($F$49:$F$496,"Comm_Intl",$N$49:$N$496),0) -> 0.36177808 | L19: =1-K19 -> 0.63822192
A20: Commercial Domestic Finance (Comm Dom) | B20: =IF($B$5="Local Currency",SUMIF(F49:F516,"Comm_Dom",M49:M516),SUMIF(F49:F516,"Comm_Dom",IF($B$5="Local Currency",M49:M516,N49:N516))) -> 255.638 | C20: {=IFERROR(SUMPRODUCT(IF($F$49:$F$516="Comm_Dom",1,0),IF($B$5="Local Currency",M49:M516,N49:N516),P49:P516)/SUMPRODUCT(IF($F$49:$F$516="Comm_Dom",1,0),IF($B$5="Local Currency",M49:M516,N49:N516)), 0)} -> 0.14234439 | D20: {=IFERROR(SUMPRODUCT(IF($F$49:$F$516="Comm_Dom",1,0),IF($B$5="Local Currency",M49:M516,N49:N516),Q49:Q516)/SUMPRODUCT(IF($F$49:$F$516="Comm_Dom",1,0),IF($B$5="Local Currency",M49:M516,N49:N516)), 0)} -> 27.867336 | E20: {=IFERROR(SUMPRODUCT(IF($F$49:$F$516="Comm_Dom",1,0),IF($B$5="Local Currency",M49:M516,N49:N516),S49:S516)/SUMPRODUCT(IF($F$49:$F$516="Comm_Dom",1,0),IF($B$5="Local Currency",M49:M516,N49:N516)), 0)} -> 1.5119036 | F20: {=IFERROR(SUMPRODUCT(IF($F$49:$F$516="Comm_Dom",1,0),IF($B$5="Local Currency",M49:M516,N49:N516),U49:U516)/SUMPRODUCT(IF($F$49:$F$516="Comm_Dom",1,0),IF($B$5="Local Currency",M49:M516,N49:N516)), 0)} -> 7.8757089 | G20: {=IFERROR(SUMPRODUCT(IF($F$49:$F$516="Comm_Dom",1,0),IF($B$5="Local Currency",M49:M516,N49:N516),V49:V516)/SUMPRODUCT(IF($F$49:$F$516="Comm_Dom",1,0),IF($B$5="Local Currency",M49:M516,N49:N516)), 0)} -> 5.2866644 | H20: {=IFERROR(SUMPRODUCT(IF($F$49:$F$516="Comm_Dom",1,0),IF($B$5="Local Currency",M49:M516,N49:N516),W49:W516)/SUMPRODUCT(IF($F$49:$F$516="Comm_Dom",1,0),IF($B$5="Local Currency",M49:M516,N49:N516)), 0)} -> 134.92901 | K20: =IFERROR(SUMIFS($N$49:$N$496,$F$49:$F$496,"Comm_Dom",$G$49:$G$496,"Loan")/SUMIF($F$49:$F$496,"Comm_Dom",$N$49:$N$496),0) -> 0.20106557 | L20: =1-K20 -> 0.79893443
B21: Equity | K21: Institution Shares
B22: ="Volume ("&$B$6&")" -> Volume (USD) | C22: Cost of Equity | D22: Term of loan | E22: Years of grace | F22: Average Annual Payment | G22: Average Annual Discounted Payment | H22: Total Discounted Payment | K22: Bilateral Agency | L22: =IFERROR(SUMIF(I49:I516, "Bilateral Agency", IF($B$5="Local Currency",M49:M516,IF($B$5="Local Currency",M49:M516,N49:N516))) / B16, 0) -> 0.40590063
A23: Total financing volumes | B23: =SUM(B24:B27) -> 2207.8601 | C23: =IFERROR(SUMPRODUCT(B24:B27,C24:C27)/SUM(B24:B27), 0) -> 0.15723629 | D23: =IFERROR(SUMPRODUCT(D24:D27,B24:B27)/SUM(B24:B27), 0) -> 29.849349 | E23: =IFERROR(SUMPRODUCT(B24:B27,E24:E27)/SUM(B24:B27),0) -> 0 | F23: =IFERROR(SUMPRODUCT(B24:B27,F24:F27)/SUM(B24:B27),0) -> 15.083811 | G23: =IFERROR(SUMPRODUCT(B24:B27,G24:G27)/SUM(B24:B27),0) -> 11.628454 | H23: =IFERROR(SUMPRODUCT(B24:B27,H24:H27)/SUM(B24:B27),0) -> 305.95661 | K23: Multilateral Agency | L23: =IFERROR(SUMIF(I49:I516, "Multilateral Agency", IF($B$5="Local Currency",M49:M516,IF($B$5="Local Currency",M49:M516,N49:N516))) / B16, 0) -> 0.31720668
A24: Concessional International Finance (Conc IFI) | B24: =IF($B$5="Local Currency",SUMIFS(M49:M516, F49:F516, "Conc_IFI", G49:G516,"Equity"),SUMIFS(IF($B$5="Local Currency",M49:M516,N49:N516), F49:F516, "Conc_IFI", G49:G516,"Equity")) -> 135.51833 | C24: {=IFERROR( SUMPRODUCT(IF($F$49:$F$516="Conc_IFI",1,0),IF($G$49:$G$516="Equity",1,0),IF($B$5="Local Currency",M49:M516,N49:N516),P49:P516)/ SUMPRODUCT(IF($F$49:$F$516="Conc_IFI",1,0),IF($G$49:$G$516="Equity",1,0),IF($B$5="Local Currency",M49:M516,N49:N516)), 0)} -> 0.15093032 | D24: {=IFERROR( SUMPRODUCT(IF($F$49:$F$516="Conc_IFI",1,0),IF($G$49:$G$516="Equity",1,0),IF($B$5="Local Currency",M49:M516,N49:N516),Q49:Q516) /SUMPRODUCT(IF($F$49:$F$516="Conc_IFI",1,0),IF($G$49:$G$516="Equity",1,0),IF($B$5="Local Currency",M49:M516,N49:N516)), 0)} -> 24.8871 | E24: {=IFERROR( SUMPRODUCT(IF($F$49:$F$516="Conc_IFI",1,0),IF($G$49:$G$516="Equity",1,0),IF($B$5="Local Currency",M49:M516,N49:N516),S49:S516)/ SUMPRODUCT(IF($F$49:$F$516="Conc_IFI",1,0),IF($G$49:$G$516="Equity",1,0),IF($B$5="Local Currency",M49:M516,N49:N516)), 0)} -> 0 | F24: {=IFERROR( SUMPRODUCT(IF($F$49:$F$516="Conc_IFI",1,0),IF($G$49:$G$516="Equity",1,0),IF($B$5="Local Currency",M49:M516,N49:N516),U49:U516)/ SUMPRODUCT(IF($F$49:$F$516="Conc_IFI",1,0),IF($G$49:$G$516="Equity",1,0),IF($B$5="Local Currency",M49:M516,N49:N516)), 0)} -> 4.4830148 | G24: {=IFERROR( SUMPRODUCT(IF($F$49:$F$516="Conc_IFI",1,0),IF($G$49:$G$516="Equity",1,0),IF($B$5="Local Currency",M49:M516,N49:N516),V49:V516)/ SUMPRODUCT(IF($F$49:$F$516="Conc_IFI",1,0),IF($G$49:$G$516="Equity",1,0),IF($B$5="Local Currency",M49:M516,N49:N516)), 0)} -> 3.4673951 | H24: {=IFERROR( SUMPRODUCT(IF($F$49:$F$516="Conc_IFI",1,0),IF($G$49:$G$516="Equity",1,0),IF($B$5="Local Currency",M49:M516,N49:N516),W49:W516)/ SUMPRODUCT(IF($F$49:$F$516="Conc_IFI",1,0),IF($G$49:$G$516="Equity",1,0),IF($B$5="Local Currency",M49:M516,N49:N516)), 0)} -> 86.61958 | K24: Foreign Government | L24: =IFERROR(SUMIF(I49:I516, "Foreign Government", IF($B$5="Local Currency",M49:M516,IF($B$5="Local Currency",M49:M516,N49:N516))) / B16, 0) -> 0.016177472
A25: Concessional Domestic Finance (Conc DPS) | B25: =IF($B$5="Local Currency",SUMIFS(M49:M516, F49:F516, "Conc_DPS", G49:G516,"Equity"),SUMIFS(IF($B$5="Local Currency",M49:M516,N49:N516),F49:F516, "Conc_DPS", G49:G516,"Equity")) -> 1014.2317 | C25: {=IFERROR( SUMPRODUCT(IF($F$49:$F$516="Conc_DPS",1,0),IF($G$49:$G$516="Equity",1,0),IF($B$5="Local Currency",M49:M516,N49:N516),P49:P516)/ SUMPRODUCT(IF($F$49:$F$516="Conc_DPS",1,0),IF($G$49:$G$516="Equity",1,0),IF($B$5="Local Currency",M49:M516,N49:N516)), 0)} -> 0.19684646 | D25: {=IFERROR( SUMPRODUCT(IF($F$49:$F$516="Conc_DPS",1,0),IF($G$49:$G$516="Equity",1,0),IF($B$5="Local Currency",M49:M516,N49:N516),Q49:Q516)/ SUMPRODUCT(IF($F$49:$F$516="Conc_DPS",1,0),IF($G$49:$G$516="Equity",1,0),IF($B$5="Local Currency",M49:M516,N49:N516)), 0)} -> 34.037672 | E25: {=IFERROR( SUMPRODUCT(IF($F$49:$F$516="Conc_DPS",1,0),IF($G$49:$G$516="Equity",1,0),IF($B$5="Local Currency",M49:M516,N49:N516),S49:S516)/ SUMPRODUCT(IF($F$49:$F$516="Conc_DPS",1,0),IF($G$49:$G$516="Equity",1,0),IF($B$5="Local Currency",M49:M516,N49:N516)), 0)} -> 0 | F25: {=IFERROR( SUMPRODUCT(IF($F$49:$F$516="Conc_DPS",1,0),IF($G$49:$G$516="Equity",1,0),IF($B$5="Local Currency",M49:M516,N49:N516),U49:U516)/ SUMPRODUCT(IF($F$49:$F$516="Conc_DPS",1,0),IF($G$49:$G$516="Equity",1,0),IF($B$5="Local Currency",M49:M516,N49:N516)), 0)} -> 25.28388 | G25: {=IFERROR( SUMPRODUCT(IF($F$49:$F$516="Conc_DPS",1,0),IF($G$49:$G$516="Equity",1,0),IF($B$5="Local Currency",M49:M516,N49:N516),V49:V516)/ SUMPRODUCT(IF($F$49:$F$516="Conc_DPS",1,0),IF($G$49:$G$516="Equity",1,0),IF($B$5="Local Currency",M49:M516,N49:N516)), 0)} -> 19.742115 | H25: {=IFERROR( SUMPRODUCT(IF($F$49:$F$516="Conc_DPS",1,0),IF($G$49:$G$516="Equity",1,0),IF($B$5="Local Currency",M49:M516,N49:N516),W49:W516)/ SUMPRODUCT(IF($F$49:$F$516="Conc_DPS",1,0),IF($G$49:$G$516="Equity",1,0),IF($B$5="Local Currency",M49:M516,N49:N516)), 0)} -> 521.77799 | K25: National Government | L25: =IFERROR(SUMIF(I49:I516, "National Government", IF($B$5="Local Currency",M49:M516,IF($B$5="Local Currency",M49:M516,N49:N516))) / B16, 0) -> 0.10071876
A26: Commercial International Finance (Comm Intl) | B26: =IF($B$5="Local Currency",SUMIFS(M49:M516,F49:F516,"Comm_Intl",G49:G516,"Equity"),SUMIFS(IF($B$5="Local Currency",M49:M516,N49:N516),F49:F516,"Comm_Intl",G49:G516,"Equity")) -> 853.872 | C26: {=IFERROR( SUMPRODUCT(IF($F$49:$F$516="Comm_Intl",1,0),IF($G$49:$G$516="Equity",1,0),IF($B$5="Local Currency",M49:M516,N49:N516),P49:P516)/ SUMPRODUCT(IF($F$49:$F$516="Comm_Intl",1,0),IF($G$49:$G$516="Equity",1,0),IF($B$5="Local Currency",M49:M516,N49:N516)), 0)} -> 0.11526586 | D26: {=IFERROR( SUMPRODUCT(IF($F$49:$F$516="Comm_Intl",1,0),IF($G$49:$G$516="Equity",1,0),IF($B$5="Local Currency",M49:M516,N49:N516),Q49:Q516)/ SUMPRODUCT(IF($F$49:$F$516="Comm_Intl",1,0),IF($G$49:$G$516="Equity",1,0),IF($B$5="Local Currency",M49:M516,N49:N516)), 0)} -> 25.574665 | E26: {=IFERROR( SUMPRODUCT(IF($F$49:$F$516="Comm_Intl",1,0),IF($G$49:$G$516="Equity",1,0),IF($B$5="Local Currency",M49:M516,N49:N516),S49:S516)/ SUMPRODUCT(IF($F$49:$F$516="Comm_Intl",1,0),IF($G$49:$G$516="Equity",1,0),IF($B$5="Local Currency",M49:M516,N49:N516)), 0)} -> 0 | F26: {=IFERROR( SUMPRODUCT(IF($F$49:$F$516="Comm_Intl",1,0),IF($G$49:$G$516="Equity",1,0),IF($B$5="Local Currency",M49:M516,N49:N516),U49:U516)/ SUMPRODUCT(IF($F$49:$F$516="Comm_Intl",1,0),IF($G$49:$G$516="Equity",1,0),IF($B$5="Local Currency",M49:M516,N49:N516)), 0)} -> 6.2906938 | G26: {=IFERROR( SUMPRODUCT(IF($F$49:$F$516="Comm_Intl",1,0),IF($G$49:$G$516="Equity",1,0),IF($B$5="Local Currency",M49:M516,N49:N516),V49:V516)/ SUMPRODUCT(IF($F$49:$F$516="Comm_Intl",1,0),IF($G$49:$G$516="Equity",1,0),IF($B$5="Local Currency",M49:M516,N49:N516)), 0)} -> 4.821005 | H26: {=IFERROR( SUMPRODUCT(IF($F$49:$F$516="Comm_Intl",1,0),IF($G$49:$G$516="Equity",1,0),IF($B$5="Local Currency",M49:M516,N49:N516),W49:W516)/ SUMPRODUCT(IF($F$49:$F$516="Comm_Intl",1,0),IF($G$49:$G$516="Equity",1,0),IF($B$5="Local Currency",M49:M516,N49:N516)), 0)} -> 123.79108 | K26: Domestic Public Sector | L26: =IFERROR(SUMIF(I49:I516, "Domestic Public Sector", IF($B$5="Local Currency",M49:M516,IF($B$5="Local Currency",M49:M516,N49:N516))) / B16, 0) -> 0
A27: Commercial Domestic Finance (Comm Dom) | B27: =IF($B$5="Local Currency",SUMIFS(M49:M516,F49:F516,"Comm_Dom",G49:G516,"Equity"),SUMIFS(IF($B$5="Local Currency",M49:M516,N49:N516),F49:F516,"Comm_Dom",G49:G516,"Equity")) -> 204.238 | C27: {=IFERROR( SUMPRODUCT(IF($F$49:$F$516="Comm_Dom",1,0),IF($G$49:$G$516="Equity",1,0),IF($B$5="Local Currency",M49:M516,N49:N516),P49:P516)/ SUMPRODUCT(IF($F$49:$F$516="Comm_Dom",1,0),IF($G$49:$G$516="Equity",1,0),IF($B$5="Local Currency",M49:M516,N49:N516)), 0)} -> 0.14018787 | D27: {=IFERROR( SUMPRODUCT(IF($F$49:$F$516="Comm_Dom",1,0),IF($G$49:$G$516="Equity",1,0),IF($B$5="Local Currency",M49:M516,N49:N516),Q49:Q516)/ SUMPRODUCT(IF($F$49:$F$516="Comm_Dom",1,0),IF($G$49:$G$516="Equity",1,0),IF($B$5="Local Currency",M49:M516,N49:N516)), 0)} -> 30.214505 | E27: {=IFERROR( SUMPRODUCT(IF($F$49:$F$516="Comm_Dom",1,0),IF($G$49:$G$516="Equity",1,0),IF($B$5="Local Currency",M49:M516,N49:N516),S49:S516)/ SUMPRODUCT(IF($F$49:$F$516="Comm_Dom",1,0),IF($G$49:$G$516="Equity",1,0),IF($B$5="Local Currency",M49:M516,N49:N516)), 0)} -> 0 | F27: {=IFERROR( SUMPRODUCT(IF($F$49:$F$516="Comm_Dom",1,0),IF($G$49:$G$516="Equity",1,0),IF($B$5="Local Currency",M49:M516,N49:N516),U49:U516)/ SUMPRODUCT(IF($F$49:$F$516="Comm_Dom",1,0),IF($G$49:$G$516="Equity",1,0),IF($B$5="Local Currency",M49:M516,N49:N516)), 0)} -> 8.2269348 | G27: {=IFERROR( SUMPRODUCT(IF($F$49:$F$516="Comm_Dom",1,0),IF($G$49:$G$516="Equity",1,0),IF($B$5="Local Currency",M49:M516,N49:N516),V49:V516)/ SUMPRODUCT(IF($F$49:$F$516="Comm_Dom",1,0),IF($G$49:$G$516="Equity",1,0),IF($B$5="Local Currency",M49:M516,N49:N516)), 0)} -> 5.2120732 | H27: {=IFERROR( SUMPRODUCT(IF($F$49:$F$516="Comm_Dom",1,0),IF($G$49:$G$516="Equity",1,0),IF($B$5="Local Currency",M49:M516,N49:N516),W49:W516)/ SUMPRODUCT(IF($F$49:$F$516="Comm_Dom",1,0),IF($G$49:$G$516="Equity",1,0),IF($B$5="Local Currency",M49:M516,N49:N516)), 0)} -> 141.33179 | K27: Climate Funds | L27: =IFERROR(SUMIF(I49:I516, "Climate Funds", IF($B$5="Local Currency",M49:M516,IF($B$5="Local Currency",M49:M516,N49:N516))) / B16, 0) -> 0.023220882
B28: Debt | K28: Commercial Bank | L28: =IFERROR(SUMIF(I49:I516, "Commercial Bank", IF($B$5="Local Currency",M49:M516,IF($B$5="Local Currency",M49:M516,N49:N516))) / B16, 0) -> 0.031322456
K29: Private Equity Fund | L29: =IFERROR(SUMIF(I49:I516, "Private Equity Fund", IF($B$5="Local Currency",M49:M516,IF($B$5="Local Currency",M49:M516,N49:N516))) / B16, 0) -> 0.10545312
B30: ="Volume ("&$B$6&")" -> Volume (USD) | C30: Cost of Debt | D30: Term of loan | E30: Years of grace | F30: Average Annual Payment | G30: Average Annual Discounted Payment | H30: Total Discounted Payment | I30: Market Element | J30: Grant Element | K30: Financing Sector Shares
A31: Total financing volumes | B31: =SUM(B32:B35) -> 8775.3146 | C31: =IFERROR(SUMPRODUCT(B32:B35,C32:C35)/SUM(B32:B35), 0) -> 0.027191343 | D31: =IFERROR(SUMPRODUCT(D32:D35,B32:B35)/SUM(B32:B35), 0) -> 26.45821 | E31: =IFERROR(SUMPRODUCT(B32:B35,E32:E35)/SUM(B32:B35),0) -> 6.7031217 | F31: =IFERROR(SUMPRODUCT(B32:B35,F32:F35)/SUM(B32:B35),0) -> 8.7527431 | G31: =IFERROR(SUMPRODUCT(B32:B35,G32:G35)/SUM(B32:B35),0) -> 6.6461533 | H31: =IFERROR(SUMPRODUCT(B32:B35,H32:H35)/SUM(B32:B35),0) -> 162.84015 | I31: =IFERROR(SUMPRODUCT(B32:B35,I32:I35)/SUM(B32:B35),0) -> 0.22371976 | J31: =IFERROR(SUMPRODUCT(B32:B35,J32:J35)/SUM(B32:B35),0) -> 0.77615489 | K31: Public Finance | L31: =IFERROR(SUMIF(H49:H516, "Public", IF($B$5="Local Currency",M49:M516,IF($B$5="Local Currency",M49:M516,N49:N516)))/B16, 0) -> 0.86302412
A32: Concessional International Finance (Conc IFI) | B32: =IF($B$5="Local Currency",SUMIFS( M49:M516, F49:F516, "Conc_IFI", G49:G516,"Loan"),SUMIFS( IF($B$5="Local Currency",M49:M516,N49:N516), F49:F516, "Conc_IFI", G49:G516,"Loan")) -> 8033.9146 | C32: {=IFERROR( SUMPRODUCT(IF($F$49:$F$516="Conc_IFI",1,0),IF($G$49:$G$516="Loan",1,0),IF($B$5="Local Currency",M49:M516,N49:N516),P49:P516)/ SUMPRODUCT(IF($F$49:$F$516="Conc_IFI",1,0),IF($G$49:$G$516="Loan",1,0),IF($B$5="Local Currency",M49:M516,N49:N516)), 0)} -> 0.022210933 | D32: {=IFERROR( SUMPRODUCT(IF($F$49:$F$516="Conc_IFI",1,0),IF($G$49:$G$516="Loan",1,0),IF($B$5="Local Currency",M49:M516,N49:N516),Q49:Q516) /SUMPRODUCT(IF($F$49:$F$516="Conc_IFI",1,0),IF($G$49:$G$516="Loan",1,0),IF($B$5="Local Currency",M49:M516,N49:N516)), 0)} -> 27.250361 | E32: {=IFERROR( SUMPRODUCT(IF($F$49:$F$516="Conc_IFI",1,0),IF($G$49:$G$516="Loan",1,0),IF($B$5="Local Currency",M49:M516,N49:N516),S49:S516)/ SUMPRODUCT(IF($F$49:$F$516="Conc_IFI",1,0),IF($G$49:$G$516="Loan",1,0),IF($B$5="Local Currency",M49:M516,N49:N516)), 0)} -> 6.9218762 | F32: {=IFERROR( SUMPRODUCT(IF($F$49:$F$516="Conc_IFI",1,0),IF($G$49:$G$516="Loan",1,0),IF($B$5="Local Currency",M49:M516,N49:N516),U49:U516)/ SUMPRODUCT(IF($F$49:$F$516="Conc_IFI",1,0),IF($G$49:$G$516="Loan",1,0),IF($B$5="Local Currency",M49:M516,N49:N516)), 0)} -> 8.9052528 | G32: {=IFERROR( SUMPRODUCT(IF($F$49:$F$516="Conc_IFI",1,0),IF($G$49:$G$516="Loan",1,0),IF($B$5="Local Currency",M49:M516,N49:N516),V49:V516)/ SUMPRODUCT(IF($F$49:$F$516="Conc_IFI",1,0),IF($G$49:$G$516="Loan",1,0),IF($B$5="Local Currency",M49:M516,N49:N516)), 0)} -> 6.6878123 | H32: {=IFERROR( SUMPRODUCT(IF($F$49:$F$516="Conc_IFI",1,0),IF($G$49:$G$516="Loan",1,0),IF($B$5="Local Currency",M49:M516,N49:N516),W49:W516)/ SUMPRODUCT(IF($F$49:$F$516="Conc_IFI",1,0),IF($G$49:$G$516="Loan",1,0),IF($B$5="Local Currency",M49:M516,N49:N516)), 0)} -> 167.95731 | I32: {=IFERROR( SUMPRODUCT(IF($F$49:$F$516="Conc_IFI",1,0),IF($G$49:$G$516="Loan",1,0),IF($B$5="Local Currency",M49:M516,N49:N516),X49:X516)/ SUMPRODUCT(IF($F$49:$F$516="Conc_IFI",1,0),IF($G$49:$G$516="Loan",1,0),IF($B$5="Local Currency",M49:M516,N49:N516),IF($G$49:$G$516="Equity",0,1)), 0)} -> 0.19386327 | J32: {=IFERROR( SUMPRODUCT(IF($F$49:$F$516="Conc_IFI",1,0),IF($G$49:$G$516="Loan",1,0),IF($B$5="Local Currency",M49:M516,N49:N516),Y49:Y516)/ SUMPRODUCT(IF($F$49:$F$516="Conc_IFI",1,0),IF($G$49:$G$516="Loan",1,0),IF($B$5="Local Currency",M49:M516,N49:N516),IF($G$49:$G$516="Equity",0,1)), 0)} -> 0.80599981 | K32: Private Finance | L32: =IFERROR(SUMIF(H49:H516, "Private", IF($B$5="Local Currency",M49:M516,IF($B$5="Local Currency",M49:M516,N49:N516))) / B16, 0) -> 0.13697588
